Workbook

Sheet Read Me
B1: DHVAJ Client Master
C2: One sheet for every client's master details, so you stop collecting GSTIN / PAN / TAN from different sites. Fill a row, and the grey columns check it and tell you what is still missing to open the client's engagements.
B4: Colours
B5: Yellow cell | C5: You fill it.
B6: Grey cell | C6: Fills itself from what you typed — do not type there.
B7: Blue row | C7: Example (Client code EXAMPLE). The import skips it.
B9: Export (portal → Excel)
B10: 1. | C10: Clients → Export client master. You get this same file with every client already in the portal, one per row, with its Client code.
B11: 2. | C11: Use the 'Ready for engagement?' column (or filter it on ✖) to see which clients still have gaps — missing GSTIN, TAN, CIN, contact, financial year…
B13: Fill
B14: Remaining clients | C14: Rows that already have a Client code: fill only the blanks. A blank cell never wipes what the portal already has.
B15: New clients | C15: Add a row with Client code left blank. Minimum: Legal name and either the GSTIN or the PAN. Type the GSTIN and the PAN, state and entity type are worked out for you.
B16: Engagements | C16: Pick the Financial year and say Yes to each service (GST, TDS / TCS, Income Tax, ROC / MCA, Bookkeeping, MIS). The import opens one Compliance engagement per client with those services. GST needs a GSTIN and a return frequency; TDS needs a TAN; ROC needs a CIN / LLPIN and is only for companies and LLPs.
B17: Several GSTINs | C17: Same PAN in several states = ONE client. Put the main GSTIN in 'GSTIN (main)' and the rest in 'Other GSTINs', separated by commas.
B18: Logins | C18: Optional. Each client's main logins — GST, Income-tax (PAN), Income-tax (TAN), TRACES, MCA, E-way bill — go in the 'Logins' columns of its row on 'Clients'. Logins of other GSTINs, TRACES taxpayer and E-invoice go on the 'Logins' sheet. Passwords are encrypted on import.
B19: Reading logins | C19: Export client master masks every password as '(saved in portal)' — importing that back changes nothing. Export with passwords writes them in full for the clients whose logins you may see (your office as partner, or your engagements); the rest stay masked. Every password exported is logged against your name.
B21: Import (Excel → portal)
B22: 1. | C22: Clients → Import client master, then choose this file.
B23: 2. | C23: The portal shows a preview first: new clients, updates (only the cells that change), engagements it will open, and every row it will skip and why. Nothing is saved yet.
B24: 3. | C24: Confirm. Rows marked ✖ are skipped; fix them and import the same file again — importing twice never creates duplicates (rows are matched by Client code, then GSTIN, then PAN).
B26: Rules
B27: Do not | C27: Rename, reorder or delete the column headings on 'Clients' and 'Logins', or edit the 'Lists' sheet.
B28: Dates | C28: dd-mm-yyyy.
B29: Entity type guess | C29: From the PAN's 4th letter: C company, P proprietorship, F firm, H HUF, A/B AOP, T trust. Pick the real type in 'Entity type' if the guess is wrong (e.g. LLP, public company, individual).
B30: Template version | C30: client-master v2

Sheet Clients
A1: DHVAJ Client Master — fill once, import into the portal, export any time
A2: Yellow = you fill · Grey = fills itself (do not type there) · Blue row 5 = example, ignored by the import · * = required · See 'Read Me' for import / export steps
A3: Client | E3: Registrations | M3: Contact | Q3: Address | V3: Engagement | AF3: Logins | AR3: Checks (fill themselves)
A4: Client code | B4: Legal name * | C4: Trade name | D4: Entity type | E4: PAN | F4: GSTIN (main) | G4: Other GSTINs | H4: TAN | I4: CIN / LLPIN | J4: Date of incorporation / birth | K4: Legal status | L4: Home office code | M4: Contact person | N4: Designation | O4: Email | P4: Mobile | Q4: Address line 1 | R4: Address line 2 | S4: City | T4: State | U4: Pincode | V4: Financial year | W4: GST | X4: GST return frequency | Y4: TDS / TCS | Z4: Income Tax | AA4: ROC / MCA | AB4: Bookkeeping | AC4: MIS | AD4: Engagement partner (email) | AE4: Lead / in-charge (email) | AF4: GST user ID | AG4: GST password | AH4: Income-tax user ID (PAN) | AI4: Income-tax password (PAN) | AJ4: Income-tax user ID (TAN) | AK4: Income-tax password (TAN) | AL4: TRACES user ID (TAN) | AM4: TRACES password | AN4: MCA user ID | AO4: MCA password | AP4: E-way bill user ID | AQ4: E-way bill password | AR4: Row type | AS4: PAN to use | AT4: Entity type to use | AU4: GST state | AV4: GSTIN check | AW4: PAN check | AX4: TAN check | AY4: Ready for engagement? | AZ4: _gstin | BA4: _pan | BB4: _type | BC4: _cat | BD4: _streams | BE4: _issues
A5: EXAMPLE | B5: Sharma Traders | C5: Sharma Electricals | F5: 07ABCPS1234K1ZO | H5: DELS12345A | J5: 42104 | K5: Active | M5: Rakesh Sharma | N5: Proprietor | O5: accounts@sharmatraders.example | P5: 9810000000 | Q5: 12, Main Market | R5: Karol Bagh | S5: New Delhi | U5: 110005 | V5: 2026-27 | W5: Yes | X5: Monthly | Y5: Yes | Z5: Yes | AA5: No | AB5: No | AC5: No | AF5: sharma_gst | AG5: •••••••• | AH5: ABCPS1234K | AI5: •••••••• | AR5: =IF(A5="EXAMPLE","Example (skipped)","") | AS5: =IF(BA5<>"",BA5,IF(LEN(AZ5)=15,MID(AZ5,3,10),"")) | AT5: =IF(BB5="","",BB5&IF(D5=""," (guessed from PAN)","")) | AU5: =IF(AZ5="","",IFERROR(INDEX(Lists!$L$2:$L$38,MATCH(LEFT(AZ5,2),Lists!$K$2:$K$38,0)),"Unknown code")) | AV5: =IF(AZ5="","",IFERROR(IF(NOT(AND(LEN(AZ5)=15,ISNUMBER(MATCH(LEFT(AZ5,2),Lists!$K$2:$K$38,0)),SUMPRODUCT(--ISERROR(FIND(MID(MID(AZ5,3,10),{1,2,3,4,5,10},1),"ABCDEFGHIJKLMNOPQRSTUVWXYZ")))=0,SUMPRODUCT(--ISERROR(FIND(MID(MID(AZ5,3,10),{6,7,8,9},1),"0123456789")))=0,ISNUMBER(FIND(MID(AZ5,13,1),"123456789ABCDEFGHIJKLMNOPQRSTUVWXYZ")),MID(AZ5,14,1)="Z")),"Wrong format",IF(MID("0123456789ABCDEFGHIJKLMNOPQRSTUVWXYZ",MOD(36-MOD(SUMPRODUCT(INT((FIND(MID(AZ5,{1,2,3,4,5,6,7,8,9,10,11,12,13,14},1),"0123456789ABCDEFGHIJKLMNOPQRSTUVWXYZ")-1)*{1,2,1,2,1,2,1,2,1,2,1,2,1,2}/36)+MOD((FIND(MID(AZ5,{1,2,3,4,5,6,7,8,9,10,11,12,13,14},1),"0123456789ABCDEFGHIJKLMNOPQRSTUVWXYZ")-1)*{1,2,1,2,1,2,1,2,1,2,1,2,1,2},36)),36),36)+1,1)=MID(AZ5,15,1),"OK","Typo? check digit wrong")),"Wrong format")) | AW5: =IF(BA5="","",IF(AND(LEN(BA5)=10,SUMPRODUCT(--ISERROR(FIND(MID(BA5,{1,2,3,4,5,10},1),"ABCDEFGHIJKLMNOPQRSTUVWXYZ")))=0,SUMPRODUCT(--ISERROR(FIND(MID(BA5,{6,7,8,9},1),"0123456789")))=0),"OK","Wrong format")) | AX5: =IF(TRIM(H5)="","",IF(AND(LEN(UPPER(TRIM(H5)))=10,SUMPRODUCT(--ISERROR(FIND(MID(UPPER(TRIM(H5)),{1,2,3,4,10},1),"ABCDEFGHIJKLMNOPQRSTUVWXYZ")))=0,SUMPRODUCT(--ISERROR(FIND(MID(UPPER(TRIM(H5)),{5,6,7,8,9},1),"0123456789")))=0),"OK","Wrong format")) | AY5: =IF(NOT(COUNTA(A5:AE5)>0),"",IF(BE5<>"","✖ "&LEFT(BE5,LEN(BE5)-2),IF(BD5>0,"✔ Ready — client + "&BD5&" service(s)","✔ Ready — client only"))) | AZ5: =UPPER(SUBSTITUTE(TRIM(F5)," ","")) | BA5: =UPPER(SUBSTITUTE(TRIM(E5)," ","")) | BB5: =IF(D5<>"",D5,IFERROR(VLOOKUP(MID(AS5,4,1),Lists!$E$2:$F$8,2,FALSE),"")) | BC5: =IFERROR(VLOOKUP(BB5,Lists!$A$2:$C$12,3,FALSE),"") | BD5: =COUNTIF(W5:AC5,"Yes") | BE5: =IF(TRIM(B5)="","Legal name missing; ","")&IF(AND(AV5<>"",AV5<>"OK"),"GSTIN: "&AV5&"; ","")&IF(AND(AW5<>"",AW5<>"OK"),"PAN wrong format; ","")&IF(AND(BA5<>"",LEN(AZ5)=15,MID(AZ5,3,10)<>BA5),"PAN does not match GSTIN; ","")&IF(AND(AX5<>"",AX5<>"OK"),"TAN wrong format; ","")&IF(AS5="","PAN missing; ","")&IF(BB5="","Entity type missing; ","")&IF(AND(AZ5<>"",COUNTIF($AZ$6:$AZ$1005,AZ5)>1),"GSTIN repeated in this sheet; ","")&IF(AND(AS5<>"",COUNTIF($AS$6:$AS$1005,AS5)>1),"PAN repeated in this sheet (same client? put extra GSTINs in Other GSTINs); ","")&IF(AND(BD5>0,V5=""),"Financial year missing; ","")&IF(AND(BD5=0,V5<>""),"Financial year given but no service is Yes; ","")&IF(AND(W5="Yes",AZ5=""),"GST needs a GSTIN; ","")&IF(AND(W5="Yes",X5=""),"GST return frequency missing; ","")&IF(AND(Y5="Yes",TRIM(H5)=""),"TDS needs a TAN; ","")&IF(AND(AA5="Yes",BC5<>"",BC5<>"company",BC5<>"llp"),"ROC is only for a company / LLP; ","")&IF(AND(AA5="Yes",OR(BC5="company",BC5="llp"),TRIM(I5)=""),"ROC needs the CIN / LLPIN; ","")&IF((TRIM(AF5)="")<>(TRIM(AG5)=""),"GST login needs both user ID and password; ","")&IF((TRIM(AH5)="")<>(TRIM(AI5)=""),"Income-tax login needs both user ID and password; ","")&IF((TRIM(AJ5)="")<>(TRIM(AK5)=""),"Income-tax login needs both user ID and password; ","")&IF((TRIM(AL5)="")<>(TRIM(AM5)=""),"TRACES login needs both user ID and password; ","")&IF((TRIM(AN5)="")<>(TRIM(AO5)=""),"MCA login needs both user ID and password; ","")&IF((TRIM(AP5)="")<>(TRIM(AQ5)=""),"E-way bill login needs both user ID and password; ","")
AR6: =IF(NOT(COUNTA(A6:AE6)>0),"",IF(A6="","New client","Update")) | AS6: =IF(BA6<>"",BA6,IF(LEN(AZ6)=15,MID(AZ6,3,10),"")) | AT6: =IF(BB6="","",BB6&IF(D6=""," (guessed from PAN)","")) | AU6: =IF(AZ6="","",IFERROR(INDEX(Lists!$L$2:$L$38,MATCH(LEFT(AZ6,2),Lists!$K$2:$K$38,0)),"Unknown code")) | AV6: =IF(AZ6="","",IFERROR(IF(NOT(AND(LEN(AZ6)=15,ISNUMBER(MATCH(LEFT(AZ6,2),Lists!$K$2:$K$38,0)),SUMPRODUCT(--ISERROR(FIND(MID(MID(AZ6,3,10),{1,2,3,4,5,10},1),"ABCDEFGHIJKLMNOPQRSTUVWXYZ")))=0,SUMPRODUCT(--ISERROR(FIND(MID(MID(AZ6,3,10),{6,7,8,9},1),"0123456789")))=0,ISNUMBER(FIND(MID(AZ6,13,1),"123456789ABCDEFGHIJKLMNOPQRSTUVWXYZ")),MID(AZ6,14,1)="Z")),"Wrong format",IF(MID("0123456789ABCDEFGHIJKLMNOPQRSTUVWXYZ",MOD(36-MOD(SUMPRODUCT(INT((FIND(MID(AZ6,{1,2,3,4,5,6,7,8,9,10,11,12,13,14},1),"0123456789ABCDEFGHIJKLMNOPQRSTUVWXYZ")-1)*{1,2,1,2,1,2,1,2,1,2,1,2,1,2}/36)+MOD((FIND(MID(AZ6,{1,2,3,4,5,6,7,8,9,10,11,12,13,14},1),"0123456789ABCDEFGHIJKLMNOPQRSTUVWXYZ")-1)*{1,2,1,2,1,2,1,2,1,2,1,2,1,2},36)),36),36)+1,1)=MID(AZ6,15,1),"OK","Typo? check digit wrong")),"Wrong format")) | AW6: =IF(BA6="","",IF(AND(LEN(BA6)=10,SUMPRODUCT(--ISERROR(FIND(MID(BA6,{1,2,3,4,5,10},1),"ABCDEFGHIJKLMNOPQRSTUVWXYZ")))=0,SUMPRODUCT(--ISERROR(FIND(MID(BA6,{6,7,8,9},1),"0123456789")))=0),"OK","Wrong format")) | AX6: =IF(TRIM(H6)="","",IF(AND(LEN(UPPER(TRIM(H6)))=10,SUMPRODUCT(--ISERROR(FIND(MID(UPPER(TRIM(H6)),{1,2,3,4,10},1),"ABCDEFGHIJKLMNOPQRSTUVWXYZ")))=0,SUMPRODUCT(--ISERROR(FIND(MID(UPPER(TRIM(H6)),{5,6,7,8,9},1),"0123456789")))=0),"OK","Wrong format")) | AY6: =IF(NOT(COUNTA(A6:AE6)>0),"",IF(BE6<>"","✖ "&LEFT(BE6,LEN(BE6)-2),IF(BD6>0,"✔ Ready — client + "&BD6&" service(s)","✔ Ready — client only"))) | AZ6: =UPPER(SUBSTITUTE(TRIM(F6)," ","")) | BA6: =UPPER(SUBSTITUTE(TRIM(E6)," ","")) | BB6: =IF(D6<>"",D6,IFERROR(VLOOKUP(MID(AS6,4,1),Lists!$E$2:$F$8,2,FALSE),"")) | BC6: =IFERROR(VLOOKUP(BB6,Lists!$A$2:$C$12,3,FALSE),"") | BD6: =COUNTIF(W6:AC6,"Yes") | BE6: =IF(TRIM(B6)="","Legal name missing; ","")&IF(AND(AV6<>"",AV6<>"OK"),"GSTIN: "&AV6&"; ","")&IF(AND(AW6<>"",AW6<>"OK"),"PAN wrong format; ","")&IF(AND(BA6<>"",LEN(AZ6)=15,MID(AZ6,3,10)<>BA6),"PAN does not match GSTIN; ","")&IF(AND(AX6<>"",AX6<>"OK"),"TAN wrong format; ","")&IF(AS6="","PAN missing; ","")&IF(BB6="","Entity type missing; ","")&IF(AND(AZ6<>"",COUNTIF($AZ$6:$AZ$1005,AZ6)>1),"GSTIN repeated in this sheet; ","")&IF(AND(AS6<>"",COUNTIF($AS$6:$AS$1005,AS6)>1),"PAN repeated in this sheet (same client? put extra GSTINs in Other GSTINs); ","")&IF(AND(BD6>0,V6=""),"Financial year missing; ","")&IF(AND(BD6=0,V6<>""),"Financial year given but no service is Yes; ","")&IF(AND(W6="Yes",AZ6=""),"GST needs a GSTIN; ","")&IF(AND(W6="Yes",X6=""),"GST return frequency missing; ","")&IF(AND(Y6="Yes",TRIM(H6)=""),"TDS needs a TAN; ","")&IF(AND(AA6="Yes",BC6<>"",BC6<>"company",BC6<>"llp"),"ROC is only for a company / LLP; ","")&IF(AND(AA6="Yes",OR(BC6="company",BC6="llp"),TRIM(I6)=""),"ROC needs the CIN / LLPIN; ","")&IF((TRIM(AF6)="")<>(TRIM(AG6)=""),"GST login needs both user ID and password; ","")&IF((TRIM(AH6)="")<>(TRIM(AI6)=""),"Income-tax login needs both user ID and password; ","")&IF((TRIM(AJ6)="")<>(TRIM(AK6)=""),"Income-tax login needs both user ID and password; ","")&IF((TRIM(AL6)="")<>(TRIM(AM6)=""),"TRACES login needs both user ID and password; ","")&IF((TRIM(AN6)="")<>(TRIM(AO6)=""),"MCA login needs both user ID and password; ","")&IF((TRIM(AP6)="")<>(TRIM(AQ6)=""),"E-way bill login needs both user ID and password; ","")
AR7: =IF(NOT(COUNTA(A7:AE7)>0),"",IF(A7="","New client","Update")) | AS7: =IF(BA7<>"",BA7,IF(LEN(AZ7)=15,MID(AZ7,3,10),"")) | AT7: =IF(BB7="","",BB7&IF(D7=""," (guessed from PAN)","")) | AU7: =IF(AZ7="","",IFERROR(INDEX(Lists!$L$2:$L$38,MATCH(LEFT(AZ7,2),Lists!$K$2:$K$38,0)),"Unknown code")) | AV7: =IF(AZ7="","",IFERROR(IF(NOT(AND(LEN(AZ7)=15,ISNUMBER(MATCH(LEFT(AZ7,2),Lists!$K$2:$K$38,0)),SUMPRODUCT(--ISERROR(FIND(MID(MID(AZ7,3,10),{1,2,3,4,5,10},1),"ABCDEFGHIJKLMNOPQRSTUVWXYZ")))=0,SUMPRODUCT(--ISERROR(FIND(MID(MID(AZ7,3,10),{6,7,8,9},1),"0123456789")))=0,ISNUMBER(FIND(MID(AZ7,13,1),"123456789ABCDEFGHIJKLMNOPQRSTUVWXYZ")),MID(AZ7,14,1)="Z")),"Wrong format",IF(MID("0123456789ABCDEFGHIJKLMNOPQRSTUVWXYZ",MOD(36-MOD(SUMPRODUCT(INT((FIND(MID(AZ7,{1,2,3,4,5,6,7,8,9,10,11,12,13,14},1),"0123456789ABCDEFGHIJKLMNOPQRSTUVWXYZ")-1)*{1,2,1,2,1,2,1,2,1,2,1,2,1,2}/36)+MOD((FIND(MID(AZ7,{1,2,3,4,5,6,7,8,9,10,11,12,13,14},1),"0123456789ABCDEFGHIJKLMNOPQRSTUVWXYZ")-1)*{1,2,1,2,1,2,1,2,1,2,1,2,1,2},36)),36),36)+1,1)=MID(AZ7,15,1),"OK","Typo? check digit wrong")),"Wrong format")) | AW7: =IF(BA7="","",IF(AND(LEN(BA7)=10,SUMPRODUCT(--ISERROR(FIND(MID(BA7,{1,2,3,4,5,10},1),"ABCDEFGHIJKLMNOPQRSTUVWXYZ")))=0,SUMPRODUCT(--ISERROR(FIND(MID(BA7,{6,7,8,9},1),"0123456789")))=0),"OK","Wrong format")) | AX7: =IF(TRIM(H7)="","",IF(AND(LEN(UPPER(TRIM(H7)))=10,SUMPRODUCT(--ISERROR(FIND(MID(UPPER(TRIM(H7)),{1,2,3,4,10},1),"ABCDEFGHIJKLMNOPQRSTUVWXYZ")))=0,SUMPRODUCT(--ISERROR(FIND(MID(UPPER(TRIM(H7)),{5,6,7,8,9},1),"0123456789")))=0),"OK","Wrong format")) | AY7: =IF(NOT(COUNTA(A7:AE7)>0),"",IF(BE7<>"","✖ "&LEFT(BE7,LEN(BE7)-2),IF(BD7>0,"✔ Ready — client + "&BD7&" service(s)","✔ Ready — client only"))) | AZ7: =UPPER(SUBSTITUTE(TRIM(F7)," ","")) | BA7: =UPPER(SUBSTITUTE(TRIM(E7)," ","")) | BB7: =IF(D7<>"",D7,IFERROR(VLOOKUP(MID(AS7,4,1),Lists!$E$2:$F$8,2,FALSE),"")) | BC7: =IFERROR(VLOOKUP(BB7,Lists!$A$2:$C$12,3,FALSE),"") | BD7: =COUNTIF(W7:AC7,"Yes") | BE7: =IF(TRIM(B7)="","Legal name missing; ","")&IF(AND(AV7<>"",AV7<>"OK"),"GSTIN: "&AV7&"; ","")&IF(AND(AW7<>"",AW7<>"OK"),"PAN wrong format; ","")&IF(AND(BA7<>"",LEN(AZ7)=15,MID(AZ7,3,10)<>BA7),"PAN does not match GSTIN; ","")&IF(AND(AX7<>"",AX7<>"OK"),"TAN wrong format; ","")&IF(AS7="","PAN missing; ","")&IF(BB7="","Entity type missing; ","")&IF(AND(AZ7<>"",COUNTIF($AZ$6:$AZ$1005,AZ7)>1),"GSTIN repeated in this sheet; ","")&IF(AND(AS7<>"",COUNTIF($AS$6:$AS$1005,AS7)>1),"PAN repeated in this sheet (same client? put extra GSTINs in Other GSTINs); ","")&IF(AND(BD7>0,V7=""),"Financial year missing; ","")&IF(AND(BD7=0,V7<>""),"Financial year given but no service is Yes; ","")&IF(AND(W7="Yes",AZ7=""),"GST needs a GSTIN; ","")&IF(AND(W7="Yes",X7=""),"GST return frequency missing; ","")&IF(AND(Y7="Yes",TRIM(H7)=""),"TDS needs a TAN; ","")&IF(AND(AA7="Yes",BC7<>"",BC7<>"company",BC7<>"llp"),"ROC is only for a company / LLP; ","")&IF(AND(AA7="Yes",OR(BC7="company",BC7="llp"),TRIM(I7)=""),"ROC needs the CIN / LLPIN; ","")&IF((TRIM(AF7)="")<>(TRIM(AG7)=""),"GST login needs both user ID and password; ","")&IF((TRIM(AH7)="")<>(TRIM(AI7)=""),"Income-tax login needs both user ID and password; ","")&IF((TRIM(AJ7)="")<>(TRIM(AK7)=""),"Income-tax login needs both user ID and password; ","")&IF((TRIM(AL7)="")<>(TRIM(AM7)=""),"TRACES login needs both user ID and password; ","")&IF((TRIM(AN7)="")<>(TRIM(AO7)=""),"MCA login needs both user ID and password; ","")&IF((TRIM(AP7)="")<>(TRIM(AQ7)=""),"E-way bill login needs both user ID and password; ","")
AR8: =IF(NOT(COUNTA(A8:AE8)>0),"",IF(A8="","New client","Update")) | AS8: =IF(BA8<>"",BA8,IF(LEN(AZ8)=15,MID(AZ8,3,10),"")) | AT8: =IF(BB8="","",BB8&IF(D8=""," (guessed from PAN)","")) | AU8: =IF(AZ8="","",IFERROR(INDEX(Lists!$L$2:$L$38,MATCH(LEFT(AZ8,2),Lists!$K$2:$K$38,0)),"Unknown code")) | AV8: =IF(AZ8="","",IFERROR(IF(NOT(AND(LEN(AZ8)=15,ISNUMBER(MATCH(LEFT(AZ8,2),Lists!$K$2:$K$38,0)),SUMPRODUCT(--ISERROR(FIND(MID(MID(AZ8,3,10),{1,2,3,4,5,10},1),"ABCDEFGHIJKLMNOPQRSTUVWXYZ")))=0,SUMPRODUCT(--ISERROR(FIND(MID(MID(AZ8,3,10),{6,7,8,9},1),"0123456789")))=0,ISNUMBER(FIND(MID(AZ8,13,1),"123456789ABCDEFGHIJKLMNOPQRSTUVWXYZ")),MID(AZ8,14,1)="Z")),"Wrong format",IF(MID("0123456789ABCDEFGHIJKLMNOPQRSTUVWXYZ",MOD(36-MOD(SUMPRODUCT(INT((FIND(MID(AZ8,{1,2,3,4,5,6,7,8,9,10,11,12,13,14},1),"0123456789ABCDEFGHIJKLMNOPQRSTUVWXYZ")-1)*{1,2,1,2,1,2,1,2,1,2,1,2,1,2}/36)+MOD((FIND(MID(AZ8,{1,2,3,4,5,6,7,8,9,10,11,12,13,14},1),"0123456789ABCDEFGHIJKLMNOPQRSTUVWXYZ")-1)*{1,2,1,2,1,2,1,2,1,2,1,2,1,2},36)),36),36)+1,1)=MID(AZ8,15,1),"OK","Typo? check digit wrong")),"Wrong format")) | AW8: =IF(BA8="","",IF(AND(LEN(BA8)=10,SUMPRODUCT(--ISERROR(FIND(MID(BA8,{1,2,3,4,5,10},1),"ABCDEFGHIJKLMNOPQRSTUVWXYZ")))=0,SUMPRODUCT(--ISERROR(FIND(MID(BA8,{6,7,8,9},1),"0123456789")))=0),"OK","Wrong format")) | AX8: =IF(TRIM(H8)="","",IF(AND(LEN(UPPER(TRIM(H8)))=10,SUMPRODUCT(--ISERROR(FIND(MID(UPPER(TRIM(H8)),{1,2,3,4,10},1),"ABCDEFGHIJKLMNOPQRSTUVWXYZ")))=0,SUMPRODUCT(--ISERROR(FIND(MID(UPPER(TRIM(H8)),{5,6,7,8,9},1),"0123456789")))=0),"OK","Wrong format")) | AY8: =IF(NOT(COUNTA(A8:AE8)>0),"",IF(BE8<>"","✖ "&LEFT(BE8,LEN(BE8)-2),IF(BD8>0,"✔ Ready — client + "&BD8&" service(s)","✔ Ready — client only"))) | AZ8: =UPPER(SUBSTITUTE(TRIM(F8)," ","")) | BA8: =UPPER(SUBSTITUTE(TRIM(E8)," ","")) | BB8: =IF(D8<>"",D8,IFERROR(VLOOKUP(MID(AS8,4,1),Lists!$E$2:$F$8,2,FALSE),"")) | BC8: =IFERROR(VLOOKUP(BB8,Lists!$A$2:$C$12,3,FALSE),"") | BD8: =COUNTIF(W8:AC8,"Yes") | BE8: =IF(TRIM(B8)="","Legal name missing; ","")&IF(AND(AV8<>"",AV8<>"OK"),"GSTIN: "&AV8&"; ","")&IF(AND(AW8<>"",AW8<>"OK"),"PAN wrong format; ","")&IF(AND(BA8<>"",LEN(AZ8)=15,MID(AZ8,3,10)<>BA8),"PAN does not match GSTIN; ","")&IF(AND(AX8<>"",AX8<>"OK"),"TAN wrong format; ","")&IF(AS8="","PAN missing; ","")&IF(BB8="","Entity type missing; ","")&IF(AND(AZ8<>"",COUNTIF($AZ$6:$AZ$1005,AZ8)>1),"GSTIN repeated in this sheet; ","")&IF(AND(AS8<>"",COUNTIF($AS$6:$AS$1005,AS8)>1),"PAN repeated in this sheet (same client? put extra GSTINs in Other GSTINs); ","")&IF(AND(BD8>0,V8=""),"Financial year missing; ","")&IF(AND(BD8=0,V8<>""),"Financial year given but no service is Yes; ","")&IF(AND(W8="Yes",AZ8=""),"GST needs a GSTIN; ","")&IF(AND(W8="Yes",X8=""),"GST return frequency missing; ","")&IF(AND(Y8="Yes",TRIM(H8)=""),"TDS needs a TAN; ","")&IF(AND(AA8="Yes",BC8<>"",BC8<>"company",BC8<>"llp"),"ROC is only for a company / LLP; ","")&IF(AND(AA8="Yes",OR(BC8="company",BC8="llp"),TRIM(I8)=""),"ROC needs the CIN / LLPIN; ","")&IF((TRIM(AF8)="")<>(TRIM(AG8)=""),"GST login needs both user ID and password; ","")&IF((TRIM(AH8)="")<>(TRIM(AI8)=""),"Income-tax login needs both user ID and password; ","")&IF((TRIM(AJ8)="")<>(TRIM(AK8)=""),"Income-tax login needs both user ID and password; ","")&IF((TRIM(AL8)="")<>(TRIM(AM8)=""),"TRACES login needs both user ID and password; ","")&IF((TRIM(AN8)="")<>(TRIM(AO8)=""),"MCA login needs both user ID and password; ","")&IF((TRIM(AP8)="")<>(TRIM(AQ8)=""),"E-way bill login needs both user ID and password; ","")
AR9: =IF(NOT(COUNTA(A9:AE9)>0),"",IF(A9="","New client","Update")) | AS9: =IF(BA9<>"",BA9,IF(LEN(AZ9)=15,MID(AZ9,3,10),"")) | AT9: =IF(BB9="","",BB9&IF(D9=""," (guessed from PAN)","")) | AU9: =IF(AZ9="","",IFERROR(INDEX(Lists!$L$2:$L$38,MATCH(LEFT(AZ9,2),Lists!$K$2:$K$38,0)),"Unknown code")) | AV9: =IF(AZ9="","",IFERROR(IF(NOT(AND(LEN(AZ9)=15,ISNUMBER(MATCH(LEFT(AZ9,2),Lists!$K$2:$K$38,0)),SUMPRODUCT(--ISERROR(FIND(MID(MID(AZ9,3,10),{1,2,3,4,5,10},1),"ABCDEFGHIJKLMNOPQRSTUVWXYZ")))=0,SUMPRODUCT(--ISERROR(FIND(MID(MID(AZ9,3,10),{6,7,8,9},1),"0123456789")))=0,ISNUMBER(FIND(MID(AZ9,13,1),"123456789ABCDEFGHIJKLMNOPQRSTUVWXYZ")),MID(AZ9,14,1)="Z")),"Wrong format",IF(MID("0123456789ABCDEFGHIJKLMNOPQRSTUVWXYZ",MOD(36-MOD(SUMPRODUCT(INT((FIND(MID(AZ9,{1,2,3,4,5,6,7,8,9,10,11,12,13,14},1),"0123456789ABCDEFGHIJKLMNOPQRSTUVWXYZ")-1)*{1,2,1,2,1,2,1,2,1,2,1,2,1,2}/36)+MOD((FIND(MID(AZ9,{1,2,3,4,5,6,7,8,9,10,11,12,13,14},1),"0123456789ABCDEFGHIJKLMNOPQRSTUVWXYZ")-1)*{1,2,1,2,1,2,1,2,1,2,1,2,1,2},36)),36),36)+1,1)=MID(AZ9,15,1),"OK","Typo? check digit wrong")),"Wrong format")) | AW9: =IF(BA9="","",IF(AND(LEN(BA9)=10,SUMPRODUCT(--ISERROR(FIND(MID(BA9,{1,2,3,4,5,10},1),"ABCDEFGHIJKLMNOPQRSTUVWXYZ")))=0,SUMPRODUCT(--ISERROR(FIND(MID(BA9,{6,7,8,9},1),"0123456789")))=0),"OK","Wrong format")) | AX9: =IF(TRIM(H9)="","",IF(AND(LEN(UPPER(TRIM(H9)))=10,SUMPRODUCT(--ISERROR(FIND(MID(UPPER(TRIM(H9)),{1,2,3,4,10},1),"ABCDEFGHIJKLMNOPQRSTUVWXYZ")))=0,SUMPRODUCT(--ISERROR(FIND(MID(UPPER(TRIM(H9)),{5,6,7,8,9},1),"0123456789")))=0),"OK","Wrong format")) | AY9: =IF(NOT(COUNTA(A9:AE9)>0),"",IF(BE9<>"","✖ "&LEFT(BE9,LEN(BE9)-2),IF(BD9>0,"✔ Ready — client + "&BD9&" service(s)","✔ Ready — client only"))) | AZ9: =UPPER(SUBSTITUTE(TRIM(F9)," ","")) | BA9: =UPPER(SUBSTITUTE(TRIM(E9)," ","")) | BB9: =IF(D9<>"",D9,IFERROR(VLOOKUP(MID(AS9,4,1),Lists!$E$2:$F$8,2,FALSE),"")) | BC9: =IFERROR(VLOOKUP(BB9,Lists!$A$2:$C$12,3,FALSE),"") | BD9: =COUNTIF(W9:AC9,"Yes") | BE9: =IF(TRIM(B9)="","Legal name missing; ","")&IF(AND(AV9<>"",AV9<>"OK"),"GSTIN: "&AV9&"; ","")&IF(AND(AW9<>"",AW9<>"OK"),"PAN wrong format; ","")&IF(AND(BA9<>"",LEN(AZ9)=15,MID(AZ9,3,10)<>BA9),"PAN does not match GSTIN; ","")&IF(AND(AX9<>"",AX9<>"OK"),"TAN wrong format; ","")&IF(AS9="","PAN missing; ","")&IF(BB9="","Entity type missing; ","")&IF(AND(AZ9<>"",COUNTIF($AZ$6:$AZ$1005,AZ9)>1),"GSTIN repeated in this sheet; ","")&IF(AND(AS9<>"",COUNTIF($AS$6:$AS$1005,AS9)>1),"PAN repeated in this sheet (same client? put extra GSTINs in Other GSTINs); ","")&IF(AND(BD9>0,V9=""),"Financial year missing; ","")&IF(AND(BD9=0,V9<>""),"Financial year given but no service is Yes; ","")&IF(AND(W9="Yes",AZ9=""),"GST needs a GSTIN; ","")&IF(AND(W9="Yes",X9=""),"GST return frequency missing; ","")&IF(AND(Y9="Yes",TRIM(H9)=""),"TDS needs a TAN; ","")&IF(AND(AA9="Yes",BC9<>"",BC9<>"company",BC9<>"llp"),"ROC is only for a company / LLP; ","")&IF(AND(AA9="Yes",OR(BC9="company",BC9="llp"),TRIM(I9)=""),"ROC needs the CIN / LLPIN; ","")&IF((TRIM(AF9)="")<>(TRIM(AG9)=""),"GST login needs both user ID and password; ","")&IF((TRIM(AH9)="")<>(TRIM(AI9)=""),"Income-tax login needs both user ID and password; ","")&IF((TRIM(AJ9)="")<>(TRIM(AK9)=""),"Income-tax login needs both user ID and password; ","")&IF((TRIM(AL9)="")<>(TRIM(AM9)=""),"TRACES login needs both user ID and password; ","")&IF((TRIM(AN9)="")<>(TRIM(AO9)=""),"MCA login needs both user ID and password; ","")&IF((TRIM(AP9)="")<>(TRIM(AQ9)=""),"E-way bill login needs both user ID and password; ","")
AR10: =IF(NOT(COUNTA(A10:AE10)>0),"",IF(A10="","New client","Update")) | AS10: =IF(BA10<>"",BA10,IF(LEN(AZ10)=15,MID(AZ10,3,10),"")) | AT10: =IF(BB10="","",BB10&IF(D10=""," (guessed from PAN)","")) | AU10: =IF(AZ10="","",IFERROR(INDEX(Lists!$L$2:$L$38,MATCH(LEFT(AZ10,2),Lists!$K$2:$K$38,0)),"Unknown code")) | AV10: =IF(AZ10="","",IFERROR(IF(NOT(AND(LEN(AZ10)=15,ISNUMBER(MATCH(LEFT(AZ10,2),Lists!$K$2:$K$38,0)),SUMPRODUCT(--ISERROR(FIND(MID(MID(AZ10,3,10),{1,2,3,4,5,10},1),"ABCDEFGHIJKLMNOPQRSTUVWXYZ")))=0,SUMPRODUCT(--ISERROR(FIND(MID(MID(AZ10,3,10),{6,7,8,9},1),"0123456789")))=0,ISNUMBER(FIND(MID(AZ10,13,1),"123456789ABCDEFGHIJKLMNOPQRSTUVWXYZ")),MID(AZ10,14,1)="Z")),"Wrong format",IF(MID("0123456789ABCDEFGHIJKLMNOPQRSTUVWXYZ",MOD(36-MOD(SUMPRODUCT(INT((FIND(MID(AZ10,{1,2,3,4,5,6,7,8,9,10,11,12,13,14},1),"0123456789ABCDEFGHIJKLMNOPQRSTUVWXYZ")-1)*{1,2,1,2,1,2,1,2,1,2,1,2,1,2}/36)+MOD((FIND(MID(AZ10,{1,2,3,4,5,6,7,8,9,10,11,12,13,14},1),"0123456789ABCDEFGHIJKLMNOPQRSTUVWXYZ")-1)*{1,2,1,2,1,2,1,2,1,2,1,2,1,2},36)),36),36)+1,1)=MID(AZ10,15,1),"OK","Typo? check digit wrong")),"Wrong format")) | AW10: =IF(BA10="","",IF(AND(LEN(BA10)=10,SUMPRODUCT(--ISERROR(FIND(MID(BA10,{1,2,3,4,5,10},1),"ABCDEFGHIJKLMNOPQRSTUVWXYZ")))=0,SUMPRODUCT(--ISERROR(FIND(MID(BA10,{6,7,8,9},1),"0123456789")))=0),"OK","Wrong format")) | AX10: =IF(TRIM(H10)="","",IF(AND(LEN(UPPER(TRIM(H10)))=10,SUMPRODUCT(--ISERROR(FIND(MID(UPPER(TRIM(H10)),{1,2,3,4,10},1),"ABCDEFGHIJKLMNOPQRSTUVWXYZ")))=0,SUMPRODUCT(--ISERROR(FIND(MID(UPPER(TRIM(H10)),{5,6,7,8,9},1),"0123456789")))=0),"OK","Wrong format")) | AY10: =IF(NOT(COUNTA(A10:AE10)>0),"",IF(BE10<>"","✖ "&LEFT(BE10,LEN(BE10)-2),IF(BD10>0,"✔ Ready — client + "&BD10&" service(s)","✔ Ready — client only"))) | AZ10: =UPPER(SUBSTITUTE(TRIM(F10)," ","")) | BA10: =UPPER(SUBSTITUTE(TRIM(E10)," ","")) | BB10: =IF(D10<>"",D10,IFERROR(VLOOKUP(MID(AS10,4,1),Lists!$E$2:$F$8,2,FALSE),"")) | BC10: =IFERROR(VLOOKUP(BB10,Lists!$A$2:$C$12,3,FALSE),"") | BD10: =COUNTIF(W10:AC10,"Yes") | BE10: =IF(TRIM(B10)="","Legal name missing; ","")&IF(AND(AV10<>"",AV10<>"OK"),"GSTIN: "&AV10&"; ","")&IF(AND(AW10<>"",AW10<>"OK"),"PAN wrong format; ","")&IF(AND(BA10<>"",LEN(AZ10)=15,MID(AZ10,3,10)<>BA10),"PAN does not match GSTIN; ","")&IF(AND(AX10<>"",AX10<>"OK"),"TAN wrong format; ","")&IF(AS10="","PAN missing; ","")&IF(BB10="","Entity type missing; ","")&IF(AND(AZ10<>"",COUNTIF($AZ$6:$AZ$1005,AZ10)>1),"GSTIN repeated in this sheet; ","")&IF(AND(AS10<>"",COUNTIF($AS$6:$AS$1005,AS10)>1),"PAN repeated in this sheet (same client? put extra GSTINs in Other GSTINs); ","")&IF(AND(BD10>0,V10=""),"Financial year missing; ","")&IF(AND(BD10=0,V10<>""),"Financial year given but no service is Yes; ","")&IF(AND(W10="Yes",AZ10=""),"GST needs a GSTIN; ","")&IF(AND(W10="Yes",X10=""),"GST return frequency missing; ","")&IF(AND(Y10="Yes",TRIM(H10)=""),"TDS needs a TAN; ","")&IF(AND(AA10="Yes",BC10<>"",BC10<>"company",BC10<>"llp"),"ROC is only for a company / LLP; ","")&IF(AND(AA10="Yes",OR(BC10="company",BC10="llp"),TRIM(I10)=""),"ROC needs the CIN / LLPIN; ","")&IF((TRIM(AF10)="")<>(TRIM(AG10)=""),"GST login needs both user ID and password; ","")&IF((TRIM(AH10)="")<>(TRIM(AI10)=""),"Income-tax login needs both user ID and password; ","")&IF((TRIM(AJ10)="")<>(TRIM(AK10)=""),"Income-tax login needs both user ID and password; ","")&IF((TRIM(AL10)="")<>(TRIM(AM10)=""),"TRACES login needs both user ID and password; ","")&IF((TRIM(AN10)="")<>(TRIM(AO10)=""),"MCA login needs both user ID and password; ","")&IF((TRIM(AP10)="")<>(TRIM(AQ10)=""),"E-way bill login needs both user ID and password; ","")
AR11: =IF(NOT(COUNTA(A11:AE11)>0),"",IF(A11="","New client","Update")) | AS11: =IF(BA11<>"",BA11,IF(LEN(AZ11)=15,MID(AZ11,3,10),"")) | AT11: =IF(BB11="","",BB11&IF(D11=""," (guessed from PAN)","")) | AU11: =IF(AZ11="","",IFERROR(INDEX(Lists!$L$2:$L$38,MATCH(LEFT(AZ11,2),Lists!$K$2:$K$38,0)),"Unknown code")) | AV11: =IF(AZ11="","",IFERROR(IF(NOT(AND(LEN(AZ11)=15,ISNUMBER(MATCH(LEFT(AZ11,2),Lists!$K$2:$K$38,0)),SUMPRODUCT(--ISERROR(FIND(MID(MID(AZ11,3,10),{1,2,3,4,5,10},1),"ABCDEFGHIJKLMNOPQRSTUVWXYZ")))=0,SUMPRODUCT(--ISERROR(FIND(MID(MID(AZ11,3,10),{6,7,8,9},1),"0123456789")))=0,ISNUMBER(FIND(MID(AZ11,13,1),"123456789ABCDEFGHIJKLMNOPQRSTUVWXYZ")),MID(AZ11,14,1)="Z")),"Wrong format",IF(MID("0123456789ABCDEFGHIJKLMNOPQRSTUVWXYZ",MOD(36-MOD(SUMPRODUCT(INT((FIND(MID(AZ11,{1,2,3,4,5,6,7,8,9,10,11,12,13,14},1),"0123456789ABCDEFGHIJKLMNOPQRSTUVWXYZ")-1)*{1,2,1,2,1,2,1,2,1,2,1,2,1,2}/36)+MOD((FIND(MID(AZ11,{1,2,3,4,5,6,7,8,9,10,11,12,13,14},1),"0123456789ABCDEFGHIJKLMNOPQRSTUVWXYZ")-1)*{1,2,1,2,1,2,1,2,1,2,1,2,1,2},36)),36),36)+1,1)=MID(AZ11,15,1),"OK","Typo? check digit wrong")),"Wrong format")) | AW11: =IF(BA11="","",IF(AND(LEN(BA11)=10,SUMPRODUCT(--ISERROR(FIND(MID(BA11,{1,2,3,4,5,10},1),"ABCDEFGHIJKLMNOPQRSTUVWXYZ")))=0,SUMPRODUCT(--ISERROR(FIND(MID(BA11,{6,7,8,9},1),"0123456789")))=0),"OK","Wrong format")) | AX11: =IF(TRIM(H11)="","",IF(AND(LEN(UPPER(TRIM(H11)))=10,SUMPRODUCT(--ISERROR(FIND(MID(UPPER(TRIM(H11)),{1,2,3,4,10},1),"ABCDEFGHIJKLMNOPQRSTUVWXYZ")))=0,SUMPRODUCT(--ISERROR(FIND(MID(UPPER(TRIM(H11)),{5,6,7,8,9},1),"0123456789")))=0),"OK","Wrong format")) | AY11: =IF(NOT(COUNTA(A11:AE11)>0),"",IF(BE11<>"","✖ "&LEFT(BE11,LEN(BE11)-2),IF(BD11>0,"✔ Ready — client + "&BD11&" service(s)","✔ Ready — client only"))) | AZ11: =UPPER(SUBSTITUTE(TRIM(F11)," ","")) | BA11: =UPPER(SUBSTITUTE(TRIM(E11)," ","")) | BB11: =IF(D11<>"",D11,IFERROR(VLOOKUP(MID(AS11,4,1),Lists!$E$2:$F$8,2,FALSE),"")) | BC11: =IFERROR(VLOOKUP(BB11,Lists!$A$2:$C$12,3,FALSE),"") | BD11: =COUNTIF(W11:AC11,"Yes") | BE11: =IF(TRIM(B11)="","Legal name missing; ","")&IF(AND(AV11<>"",AV11<>"OK"),"GSTIN: "&AV11&"; ","")&IF(AND(AW11<>"",AW11<>"OK"),"PAN wrong format; ","")&IF(AND(BA11<>"",LEN(AZ11)=15,MID(AZ11,3,10)<>BA11),"PAN does not match GSTIN; ","")&IF(AND(AX11<>"",AX11<>"OK"),"TAN wrong format; ","")&IF(AS11="","PAN missing; ","")&IF(BB11="","Entity type missing; ","")&IF(AND(AZ11<>"",COUNTIF($AZ$6:$AZ$1005,AZ11)>1),"GSTIN repeated in this sheet; ","")&IF(AND(AS11<>"",COUNTIF($AS$6:$AS$1005,AS11)>1),"PAN repeated in this sheet (same client? put extra GSTINs in Other GSTINs); ","")&IF(AND(BD11>0,V11=""),"Financial year missing; ","")&IF(AND(BD11=0,V11<>""),"Financial year given but no service is Yes; ","")&IF(AND(W11="Yes",AZ11=""),"GST needs a GSTIN; ","")&IF(AND(W11="Yes",X11=""),"GST return frequency missing; ","")&IF(AND(Y11="Yes",TRIM(H11)=""),"TDS needs a TAN; ","")&IF(AND(AA11="Yes",BC11<>"",BC11<>"company",BC11<>"llp"),"ROC is only for a company / LLP; ","")&IF(AND(AA11="Yes",OR(BC11="company",BC11="llp"),TRIM(I11)=""),"ROC needs the CIN / LLPIN; ","")&IF((TRIM(AF11)="")<>(TRIM(AG11)=""),"GST login needs both user ID and password; ","")&IF((TRIM(AH11)="")<>(TRIM(AI11)=""),"Income-tax login needs both user ID and password; ","")&IF((TRIM(AJ11)="")<>(TRIM(AK11)=""),"Income-tax login needs both user ID and password; ","")&IF((TRIM(AL11)="")<>(TRIM(AM11)=""),"TRACES login needs both user ID and password; ","")&IF((TRIM(AN11)="")<>(TRIM(AO11)=""),"MCA login needs both user ID and password; ","")&IF((TRIM(AP11)="")<>(TRIM(AQ11)=""),"E-way bill login needs both user ID and password; ","")
AR12: =IF(NOT(COUNTA(A12:AE12)>0),"",IF(A12="","New client","Update")) | AS12: =IF(BA12<>"",BA12,IF(LEN(AZ12)=15,MID(AZ12,3,10),"")) | AT12: =IF(BB12="","",BB12&IF(D12=""," (guessed from PAN)","")) | AU12: =IF(AZ12="","",IFERROR(INDEX(Lists!$L$2:$L$38,MATCH(LEFT(AZ12,2),Lists!$K$2:$K$38,0)),"Unknown code")) | AV12: =IF(AZ12="","",IFERROR(IF(NOT(AND(LEN(AZ12)=15,ISNUMBER(MATCH(LEFT(AZ12,2),Lists!$K$2:$K$38,0)),SUMPRODUCT(--ISERROR(FIND(MID(MID(AZ12,3,10),{1,2,3,4,5,10},1),"ABCDEFGHIJKLMNOPQRSTUVWXYZ")))=0,SUMPRODUCT(--ISERROR(FIND(MID(MID(AZ12,3,10),{6,7,8,9},1),"0123456789")))=0,ISNUMBER(FIND(MID(AZ12,13,1),"123456789ABCDEFGHIJKLMNOPQRSTUVWXYZ")),MID(AZ12,14,1)="Z")),"Wrong format",IF(MID("0123456789ABCDEFGHIJKLMNOPQRSTUVWXYZ",MOD(36-MOD(SUMPRODUCT(INT((FIND(MID(AZ12,{1,2,3,4,5,6,7,8,9,10,11,12,13,14},1),"0123456789ABCDEFGHIJKLMNOPQRSTUVWXYZ")-1)*{1,2,1,2,1,2,1,2,1,2,1,2,1,2}/36)+MOD((FIND(MID(AZ12,{1,2,3,4,5,6,7,8,9,10,11,12,13,14},1),"0123456789ABCDEFGHIJKLMNOPQRSTUVWXYZ")-1)*{1,2,1,2,1,2,1,2,1,2,1,2,1,2},36)),36),36)+1,1)=MID(AZ12,15,1),"OK","Typo? check digit wrong")),"Wrong format")) | AW12: =IF(BA12="","",IF(AND(LEN(BA12)=10,SUMPRODUCT(--ISERROR(FIND(MID(BA12,{1,2,3,4,5,10},1),"ABCDEFGHIJKLMNOPQRSTUVWXYZ")))=0,SUMPRODUCT(--ISERROR(FIND(MID(BA12,{6,7,8,9},1),"0123456789")))=0),"OK","Wrong format")) | AX12: =IF(TRIM(H12)="","",IF(AND(LEN(UPPER(TRIM(H12)))=10,SUMPRODUCT(--ISERROR(FIND(MID(UPPER(TRIM(H12)),{1,2,3,4,10},1),"ABCDEFGHIJKLMNOPQRSTUVWXYZ")))=0,SUMPRODUCT(--ISERROR(FIND(MID(UPPER(TRIM(H12)),{5,6,7,8,9},1),"0123456789")))=0),"OK","Wrong format")) | AY12: =IF(NOT(COUNTA(A12:AE12)>0),"",IF(BE12<>"","✖ "&LEFT(BE12,LEN(BE12)-2),IF(BD12>0,"✔ Ready — client + "&BD12&" service(s)","✔ Ready — client only"))) | AZ12: =UPPER(SUBSTITUTE(TRIM(F12)," ","")) | BA12: =UPPER(SUBSTITUTE(TRIM(E12)," ","")) | BB12: =IF(D12<>"",D12,IFERROR(VLOOKUP(MID(AS12,4,1),Lists!$E$2:$F$8,2,FALSE),"")) | BC12: =IFERROR(VLOOKUP(BB12,Lists!$A$2:$C$12,3,FALSE),"") | BD12: =COUNTIF(W12:AC12,"Yes") | BE12: =IF(TRIM(B12)="","Legal name missing; ","")&IF(AND(AV12<>"",AV12<>"OK"),"GSTIN: "&AV12&"; ","")&IF(AND(AW12<>"",AW12<>"OK"),"PAN wrong format; ","")&IF(AND(BA12<>"",LEN(AZ12)=15,MID(AZ12,3,10)<>BA12),"PAN does not match GSTIN; ","")&IF(AND(AX12<>"",AX12<>"OK"),"TAN wrong format; ","")&IF(AS12="","PAN missing; ","")&IF(BB12="","Entity type missing; ","")&IF(AND(AZ12<>"",COUNTIF($AZ$6:$AZ$1005,AZ12)>1),"GSTIN repeated in this sheet; ","")&IF(AND(AS12<>"",COUNTIF($AS$6:$AS$1005,AS12)>1),"PAN repeated in this sheet (same client? put extra GSTINs in Other GSTINs); ","")&IF(AND(BD12>0,V12=""),"Financial year missing; ","")&IF(AND(BD12=0,V12<>""),"Financial year given but no service is Yes; ","")&IF(AND(W12="Yes",AZ12=""),"GST needs a GSTIN; ","")&IF(AND(W12="Yes",X12=""),"GST return frequency missing; ","")&IF(AND(Y12="Yes",TRIM(H12)=""),"TDS needs a TAN; ","")&IF(AND(AA12="Yes",BC12<>"",BC12<>"company",BC12<>"llp"),"ROC is only for a company / LLP; ","")&IF(AND(AA12="Yes",OR(BC12="company",BC12="llp"),TRIM(I12)=""),"ROC needs the CIN / LLPIN; ","")&IF((TRIM(AF12)="")<>(TRIM(AG12)=""),"GST login needs both user ID and password; ","")&IF((TRIM(AH12)="")<>(TRIM(AI12)=""),"Income-tax login needs both user ID and password; ","")&IF((TRIM(AJ12)="")<>(TRIM(AK12)=""),"Income-tax login needs both user ID and password; ","")&IF((TRIM(AL12)="")<>(TRIM(AM12)=""),"TRACES login needs both user ID and password; ","")&IF((TRIM(AN12)="")<>(TRIM(AO12)=""),"MCA login needs both user ID and password; ","")&IF((TRIM(AP12)="")<>(TRIM(AQ12)=""),"E-way bill login needs both user ID and password; ","")
AR13: =IF(NOT(COUNTA(A13:AE13)>0),"",IF(A13="","New client","Update")) | AS13: =IF(BA13<>"",BA13,IF(LEN(AZ13)=15,MID(AZ13,3,10),"")) | AT13: =IF(BB13="","",BB13&IF(D13=""," (guessed from PAN)","")) | AU13: =IF(AZ13="","",IFERROR(INDEX(Lists!$L$2:$L$38,MATCH(LEFT(AZ13,2),Lists!$K$2:$K$38,0)),"Unknown code")) | AV13: =IF(AZ13="","",IFERROR(IF(NOT(AND(LEN(AZ13)=15,ISNUMBER(MATCH(LEFT(AZ13,2),Lists!$K$2:$K$38,0)),SUMPRODUCT(--ISERROR(FIND(MID(MID(AZ13,3,10),{1,2,3,4,5,10},1),"ABCDEFGHIJKLMNOPQRSTUVWXYZ")))=0,SUMPRODUCT(--ISERROR(FIND(MID(MID(AZ13,3,10),{6,7,8,9},1),"0123456789")))=0,ISNUMBER(FIND(MID(AZ13,13,1),"123456789ABCDEFGHIJKLMNOPQRSTUVWXYZ")),MID(AZ13,14,1)="Z")),"Wrong format",IF(MID("0123456789ABCDEFGHIJKLMNOPQRSTUVWXYZ",MOD(36-MOD(SUMPRODUCT(INT((FIND(MID(AZ13,{1,2,3,4,5,6,7,8,9,10,11,12,13,14},1),"0123456789ABCDEFGHIJKLMNOPQRSTUVWXYZ")-1)*{1,2,1,2,1,2,1,2,1,2,1,2,1,2}/36)+MOD((FIND(MID(AZ13,{1,2,3,4,5,6,7,8,9,10,11,12,13,14},1),"0123456789ABCDEFGHIJKLMNOPQRSTUVWXYZ")-1)*{1,2,1,2,1,2,1,2,1,2,1,2,1,2},36)),36),36)+1,1)=MID(AZ13,15,1),"OK","Typo? check digit wrong")),"Wrong format")) | AW13: =IF(BA13="","",IF(AND(LEN(BA13)=10,SUMPRODUCT(--ISERROR(FIND(MID(BA13,{1,2,3,4,5,10},1),"ABCDEFGHIJKLMNOPQRSTUVWXYZ")))=0,SUMPRODUCT(--ISERROR(FIND(MID(BA13,{6,7,8,9},1),"0123456789")))=0),"OK","Wrong format")) | AX13: =IF(TRIM(H13)="","",IF(AND(LEN(UPPER(TRIM(H13)))=10,SUMPRODUCT(--ISERROR(FIND(MID(UPPER(TRIM(H13)),{1,2,3,4,10},1),"ABCDEFGHIJKLMNOPQRSTUVWXYZ")))=0,SUMPRODUCT(--ISERROR(FIND(MID(UPPER(TRIM(H13)),{5,6,7,8,9},1),"0123456789")))=0),"OK","Wrong format")) | AY13: =IF(NOT(COUNTA(A13:AE13)>0),"",IF(BE13<>"","✖ "&LEFT(BE13,LEN(BE13)-2),IF(BD13>0,"✔ Ready — client + "&BD13&" service(s)","✔ Ready — client only"))) | AZ13: =UPPER(SUBSTITUTE(TRIM(F13)," ","")) | BA13: =UPPER(SUBSTITUTE(TRIM(E13)," ","")) | BB13: =IF(D13<>"",D13,IFERROR(VLOOKUP(MID(AS13,4,1),Lists!$E$2:$F$8,2,FALSE),"")) | BC13: =IFERROR(VLOOKUP(BB13,Lists!$A$2:$C$12,3,FALSE),"") | BD13: =COUNTIF(W13:AC13,"Yes") | BE13: =IF(TRIM(B13)="","Legal name missing; ","")&IF(AND(AV13<>"",AV13<>"OK"),"GSTIN: "&AV13&"; ","")&IF(AND(AW13<>"",AW13<>"OK"),"PAN wrong format; ","")&IF(AND(BA13<>"",LEN(AZ13)=15,MID(AZ13,3,10)<>BA13),"PAN does not match GSTIN; ","")&IF(AND(AX13<>"",AX13<>"OK"),"TAN wrong format; ","")&IF(AS13="","PAN missing; ","")&IF(BB13="","Entity type missing; ","")&IF(AND(AZ13<>"",COUNTIF($AZ$6:$AZ$1005,AZ13)>1),"GSTIN repeated in this sheet; ","")&IF(AND(AS13<>"",COUNTIF($AS$6:$AS$1005,AS13)>1),"PAN repeated in this sheet (same client? put extra GSTINs in Other GSTINs); ","")&IF(AND(BD13>0,V13=""),"Financial year missing; ","")&IF(AND(BD13=0,V13<>""),"Financial year given but no service is Yes; ","")&IF(AND(W13="Yes",AZ13=""),"GST needs a GSTIN; ","")&IF(AND(W13="Yes",X13=""),"GST return frequency missing; ","")&IF(AND(Y13="Yes",TRIM(H13)=""),"TDS needs a TAN; ","")&IF(AND(AA13="Yes",BC13<>"",BC13<>"company",BC13<>"llp"),"ROC is only for a company / LLP; ","")&IF(AND(AA13="Yes",OR(BC13="company",BC13="llp"),TRIM(I13)=""),"ROC needs the CIN / LLPIN; ","")&IF((TRIM(AF13)="")<>(TRIM(AG13)=""),"GST login needs both user ID and password; ","")&IF((TRIM(AH13)="")<>(TRIM(AI13)=""),"Income-tax login needs both user ID and password; ","")&IF((TRIM(AJ13)="")<>(TRIM(AK13)=""),"Income-tax login needs both user ID and password; ","")&IF((TRIM(AL13)="")<>(TRIM(AM13)=""),"TRACES login needs both user ID and password; ","")&IF((TRIM(AN13)="")<>(TRIM(AO13)=""),"MCA login needs both user ID and password; ","")&IF((TRIM(AP13)="")<>(TRIM(AQ13)=""),"E-way bill login needs both user ID and password; ","")
AR14: =IF(NOT(COUNTA(A14:AE14)>0),"",IF(A14="","New client","Update")) | AS14: =IF(BA14<>"",BA14,IF(LEN(AZ14)=15,MID(AZ14,3,10),"")) | AT14: =IF(BB14="","",BB14&IF(D14=""," (guessed from PAN)","")) | AU14: =IF(AZ14="","",IFERROR(INDEX(Lists!$L$2:$L$38,MATCH(LEFT(AZ14,2),Lists!$K$2:$K$38,0)),"Unknown code")) | AV14: =IF(AZ14="","",IFERROR(IF(NOT(AND(LEN(AZ14)=15,ISNUMBER(MATCH(LEFT(AZ14,2),Lists!$K$2:$K$38,0)),SUMPRODUCT(--ISERROR(FIND(MID(MID(AZ14,3,10),{1,2,3,4,5,10},1),"ABCDEFGHIJKLMNOPQRSTUVWXYZ")))=0,SUMPRODUCT(--ISERROR(FIND(MID(MID(AZ14,3,10),{6,7,8,9},1),"0123456789")))=0,ISNUMBER(FIND(MID(AZ14,13,1),"123456789ABCDEFGHIJKLMNOPQRSTUVWXYZ")),MID(AZ14,14,1)="Z")),"Wrong format",IF(MID("0123456789ABCDEFGHIJKLMNOPQRSTUVWXYZ",MOD(36-MOD(SUMPRODUCT(INT((FIND(MID(AZ14,{1,2,3,4,5,6,7,8,9,10,11,12,13,14},1),"0123456789ABCDEFGHIJKLMNOPQRSTUVWXYZ")-1)*{1,2,1,2,1,2,1,2,1,2,1,2,1,2}/36)+MOD((FIND(MID(AZ14,{1,2,3,4,5,6,7,8,9,10,11,12,13,14},1),"0123456789ABCDEFGHIJKLMNOPQRSTUVWXYZ")-1)*{1,2,1,2,1,2,1,2,1,2,1,2,1,2},36)),36),36)+1,1)=MID(AZ14,15,1),"OK","Typo? check digit wrong")),"Wrong format")) | AW14: =IF(BA14="","",IF(AND(LEN(BA14)=10,SUMPRODUCT(--ISERROR(FIND(MID(BA14,{1,2,3,4,5,10},1),"ABCDEFGHIJKLMNOPQRSTUVWXYZ")))=0,SUMPRODUCT(--ISERROR(FIND(MID(BA14,{6,7,8,9},1),"0123456789")))=0),"OK","Wrong format")) | AX14: =IF(TRIM(H14)="","",IF(AND(LEN(UPPER(TRIM(H14)))=10,SUMPRODUCT(--ISERROR(FIND(MID(UPPER(TRIM(H14)),{1,2,3,4,10},1),"ABCDEFGHIJKLMNOPQRSTUVWXYZ")))=0,SUMPRODUCT(--ISERROR(FIND(MID(UPPER(TRIM(H14)),{5,6,7,8,9},1),"0123456789")))=0),"OK","Wrong format")) | AY14: =IF(NOT(COUNTA(A14:AE14)>0),"",IF(BE14<>"","✖ "&LEFT(BE14,LEN(BE14)-2),IF(BD14>0,"✔ Ready — client + "&BD14&" service(s)","✔ Ready — client only"))) | AZ14: =UPPER(SUBSTITUTE(TRIM(F14)," ","")) | BA14: =UPPER(SUBSTITUTE(TRIM(E14)," ","")) | BB14: =IF(D14<>"",D14,IFERROR(VLOOKUP(MID(AS14,4,1),Lists!$E$2:$F$8,2,FALSE),"")) | BC14: =IFERROR(VLOOKUP(BB14,Lists!$A$2:$C$12,3,FALSE),"") | BD14: =COUNTIF(W14:AC14,"Yes") | BE14: =IF(TRIM(B14)="","Legal name missing; ","")&IF(AND(AV14<>"",AV14<>"OK"),"GSTIN: "&AV14&"; ","")&IF(AND(AW14<>"",AW14<>"OK"),"PAN wrong format; ","")&IF(AND(BA14<>"",LEN(AZ14)=15,MID(AZ14,3,10)<>BA14),"PAN does not match GSTIN; ","")&IF(AND(AX14<>"",AX14<>"OK"),"TAN wrong format; ","")&IF(AS14="","PAN missing; ","")&IF(BB14="","Entity type missing; ","")&IF(AND(AZ14<>"",COUNTIF($AZ$6:$AZ$1005,AZ14)>1),"GSTIN repeated in this sheet; ","")&IF(AND(AS14<>"",COUNTIF($AS$6:$AS$1005,AS14)>1),"PAN repeated in this sheet (same client? put extra GSTINs in Other GSTINs); ","")&IF(AND(BD14>0,V14=""),"Financial year missing; ","")&IF(AND(BD14=0,V14<>""),"Financial year given but no service is Yes; ","")&IF(AND(W14="Yes",AZ14=""),"GST needs a GSTIN; ","")&IF(AND(W14="Yes",X14=""),"GST return frequency missing; ","")&IF(AND(Y14="Yes",TRIM(H14)=""),"TDS needs a TAN; ","")&IF(AND(AA14="Yes",BC14<>"",BC14<>"company",BC14<>"llp"),"ROC is only for a company / LLP; ","")&IF(AND(AA14="Yes",OR(BC14="company",BC14="llp"),TRIM(I14)=""),"ROC needs the CIN / LLPIN; ","")&IF((TRIM(AF14)="")<>(TRIM(AG14)=""),"GST login needs both user ID and password; ","")&IF((TRIM(AH14)="")<>(TRIM(AI14)=""),"Income-tax login needs both user ID and password; ","")&IF((TRIM(AJ14)="")<>(TRIM(AK14)=""),"Income-tax login needs both user ID and password; ","")&IF((TRIM(AL14)="")<>(TRIM(AM14)=""),"TRACES login needs both user ID and password; ","")&IF((TRIM(AN14)="")<>(TRIM(AO14)=""),"MCA login needs both user ID and password; ","")&IF((TRIM(AP14)="")<>(TRIM(AQ14)=""),"E-way bill login needs both user ID and password; ","")
AR15: =IF(NOT(COUNTA(A15:AE15)>0),"",IF(A15="","New client","Update")) | AS15: =IF(BA15<>"",BA15,IF(LEN(AZ15)=15,MID(AZ15,3,10),"")) | AT15: =IF(BB15="","",BB15&IF(D15=""," (guessed from PAN)","")) | AU15: =IF(AZ15="","",IFERROR(INDEX(Lists!$L$2:$L$38,MATCH(LEFT(AZ15,2),Lists!$K$2:$K$38,0)),"Unknown code")) | AV15: =IF(AZ15="","",IFERROR(IF(NOT(AND(LEN(AZ15)=15,ISNUMBER(MATCH(LEFT(AZ15,2),Lists!$K$2:$K$38,0)),SUMPRODUCT(--ISERROR(FIND(MID(MID(AZ15,3,10),{1,2,3,4,5,10},1),"ABCDEFGHIJKLMNOPQRSTUVWXYZ")))=0,SUMPRODUCT(--ISERROR(FIND(MID(MID(AZ15,3,10),{6,7,8,9},1),"0123456789")))=0,ISNUMBER(FIND(MID(AZ15,13,1),"123456789ABCDEFGHIJKLMNOPQRSTUVWXYZ")),MID(AZ15,14,1)="Z")),"Wrong format",IF(MID("0123456789ABCDEFGHIJKLMNOPQRSTUVWXYZ",MOD(36-MOD(SUMPRODUCT(INT((FIND(MID(AZ15,{1,2,3,4,5,6,7,8,9,10,11,12,13,14},1),"0123456789ABCDEFGHIJKLMNOPQRSTUVWXYZ")-1)*{1,2,1,2,1,2,1,2,1,2,1,2,1,2}/36)+MOD((FIND(MID(AZ15,{1,2,3,4,5,6,7,8,9,10,11,12,13,14},1),"0123456789ABCDEFGHIJKLMNOPQRSTUVWXYZ")-1)*{1,2,1,2,1,2,1,2,1,2,1,2,1,2},36)),36),36)+1,1)=MID(AZ15,15,1),"OK","Typo? check digit wrong")),"Wrong format")) | AW15: =IF(BA15="","",IF(AND(LEN(BA15)=10,SUMPRODUCT(--ISERROR(FIND(MID(BA15,{1,2,3,4,5,10},1),"ABCDEFGHIJKLMNOPQRSTUVWXYZ")))=0,SUMPRODUCT(--ISERROR(FIND(MID(BA15,{6,7,8,9},1),"0123456789")))=0),"OK","Wrong format")) | AX15: =IF(TRIM(H15)="","",IF(AND(LEN(UPPER(TRIM(H15)))=10,SUMPRODUCT(--ISERROR(FIND(MID(UPPER(TRIM(H15)),{1,2,3,4,10},1),"ABCDEFGHIJKLMNOPQRSTUVWXYZ")))=0,SUMPRODUCT(--ISERROR(FIND(MID(UPPER(TRIM(H15)),{5,6,7,8,9},1),"0123456789")))=0),"OK","Wrong format")) | AY15: =IF(NOT(COUNTA(A15:AE15)>0),"",IF(BE15<>"","✖ "&LEFT(BE15,LEN(BE15)-2),IF(BD15>0,"✔ Ready — client + "&BD15&" service(s)","✔ Ready — client only"))) | AZ15: =UPPER(SUBSTITUTE(TRIM(F15)," ","")) | BA15: =UPPER(SUBSTITUTE(TRIM(E15)," ","")) | BB15: =IF(D15<>"",D15,IFERROR(VLOOKUP(MID(AS15,4,1),Lists!$E$2:$F$8,2,FALSE),"")) | BC15: =IFERROR(VLOOKUP(BB15,Lists!$A$2:$C$12,3,FALSE),"") | BD15: =COUNTIF(W15:AC15,"Yes") | BE15: =IF(TRIM(B15)="","Legal name missing; ","")&IF(AND(AV15<>"",AV15<>"OK"),"GSTIN: "&AV15&"; ","")&IF(AND(AW15<>"",AW15<>"OK"),"PAN wrong format; ","")&IF(AND(BA15<>"",LEN(AZ15)=15,MID(AZ15,3,10)<>BA15),"PAN does not match GSTIN; ","")&IF(AND(AX15<>"",AX15<>"OK"),"TAN wrong format; ","")&IF(AS15="","PAN missing; ","")&IF(BB15="","Entity type missing; ","")&IF(AND(AZ15<>"",COUNTIF($AZ$6:$AZ$1005,AZ15)>1),"GSTIN repeated in this sheet; ","")&IF(AND(AS15<>"",COUNTIF($AS$6:$AS$1005,AS15)>1),"PAN repeated in this sheet (same client? put extra GSTINs in Other GSTINs); ","")&IF(AND(BD15>0,V15=""),"Financial year missing; ","")&IF(AND(BD15=0,V15<>""),"Financial year given but no service is Yes; ","")&IF(AND(W15="Yes",AZ15=""),"GST needs a GSTIN; ","")&IF(AND(W15="Yes",X15=""),"GST return frequency missing; ","")&IF(AND(Y15="Yes",TRIM(H15)=""),"TDS needs a TAN; ","")&IF(AND(AA15="Yes",BC15<>"",BC15<>"company",BC15<>"llp"),"ROC is only for a company / LLP; ","")&IF(AND(AA15="Yes",OR(BC15="company",BC15="llp"),TRIM(I15)=""),"ROC needs the CIN / LLPIN; ","")&IF((TRIM(AF15)="")<>(TRIM(AG15)=""),"GST login needs both user ID and password; ","")&IF((TRIM(AH15)="")<>(TRIM(AI15)=""),"Income-tax login needs both user ID and password; ","")&IF((TRIM(AJ15)="")<>(TRIM(AK15)=""),"Income-tax login needs both user ID and password; ","")&IF((TRIM(AL15)="")<>(TRIM(AM15)=""),"TRACES login needs both user ID and password; ","")&IF((TRIM(AN15)="")<>(TRIM(AO15)=""),"MCA login needs both user ID and password; ","")&IF((TRIM(AP15)="")<>(TRIM(AQ15)=""),"E-way bill login needs both user ID and password; ","")
AR16: =IF(NOT(COUNTA(A16:AE16)>0),"",IF(A16="","New client","Update")) | AS16: =IF(BA16<>"",BA16,IF(LEN(AZ16)=15,MID(AZ16,3,10),"")) | AT16: =IF(BB16="","",BB16&IF(D16=""," (guessed from PAN)","")) | AU16: =IF(AZ16="","",IFERROR(INDEX(Lists!$L$2:$L$38,MATCH(LEFT(AZ16,2),Lists!$K$2:$K$38,0)),"Unknown code")) | AV16: =IF(AZ16="","",IFERROR(IF(NOT(AND(LEN(AZ16)=15,ISNUMBER(MATCH(LEFT(AZ16,2),Lists!$K$2:$K$38,0)),SUMPRODUCT(--ISERROR(FIND(MID(MID(AZ16,3,10),{1,2,3,4,5,10},1),"ABCDEFGHIJKLMNOPQRSTUVWXYZ")))=0,SUMPRODUCT(--ISERROR(FIND(MID(MID(AZ16,3,10),{6,7,8,9},1),"0123456789")))=0,ISNUMBER(FIND(MID(AZ16,13,1),"123456789ABCDEFGHIJKLMNOPQRSTUVWXYZ")),MID(AZ16,14,1)="Z")),"Wrong format",IF(MID("0123456789ABCDEFGHIJKLMNOPQRSTUVWXYZ",MOD(36-MOD(SUMPRODUCT(INT((FIND(MID(AZ16,{1,2,3,4,5,6,7,8,9,10,11,12,13,14},1),"0123456789ABCDEFGHIJKLMNOPQRSTUVWXYZ")-1)*{1,2,1,2,1,2,1,2,1,2,1,2,1,2}/36)+MOD((FIND(MID(AZ16,{1,2,3,4,5,6,7,8,9,10,11,12,13,14},1),"0123456789ABCDEFGHIJKLMNOPQRSTUVWXYZ")-1)*{1,2,1,2,1,2,1,2,1,2,1,2,1,2},36)),36),36)+1,1)=MID(AZ16,15,1),"OK","Typo? check digit wrong")),"Wrong format")) | AW16: =IF(BA16="","",IF(AND(LEN(BA16)=10,SUMPRODUCT(--ISERROR(FIND(MID(BA16,{1,2,3,4,5,10},1),"ABCDEFGHIJKLMNOPQRSTUVWXYZ")))=0,SUMPRODUCT(--ISERROR(FIND(MID(BA16,{6,7,8,9},1),"0123456789")))=0),"OK","Wrong format")) | AX16: =IF(TRIM(H16)="","",IF(AND(LEN(UPPER(TRIM(H16)))=10,SUMPRODUCT(--ISERROR(FIND(MID(UPPER(TRIM(H16)),{1,2,3,4,10},1),"ABCDEFGHIJKLMNOPQRSTUVWXYZ")))=0,SUMPRODUCT(--ISERROR(FIND(MID(UPPER(TRIM(H16)),{5,6,7,8,9},1),"0123456789")))=0),"OK","Wrong format")) | AY16: =IF(NOT(COUNTA(A16:AE16)>0),"",IF(BE16<>"","✖ "&LEFT(BE16,LEN(BE16)-2),IF(BD16>0,"✔ Ready — client + "&BD16&" service(s)","✔ Ready — client only"))) | AZ16: =UPPER(SUBSTITUTE(TRIM(F16)," ","")) | BA16: =UPPER(SUBSTITUTE(TRIM(E16)," ","")) | BB16: =IF(D16<>"",D16,IFERROR(VLOOKUP(MID(AS16,4,1),Lists!$E$2:$F$8,2,FALSE),"")) | BC16: =IFERROR(VLOOKUP(BB16,Lists!$A$2:$C$12,3,FALSE),"") | BD16: =COUNTIF(W16:AC16,"Yes") | BE16: =IF(TRIM(B16)="","Legal name missing; ","")&IF(AND(AV16<>"",AV16<>"OK"),"GSTIN: "&AV16&"; ","")&IF(AND(AW16<>"",AW16<>"OK"),"PAN wrong format; ","")&IF(AND(BA16<>"",LEN(AZ16)=15,MID(AZ16,3,10)<>BA16),"PAN does not match GSTIN; ","")&IF(AND(AX16<>"",AX16<>"OK"),"TAN wrong format; ","")&IF(AS16="","PAN missing; ","")&IF(BB16="","Entity type missing; ","")&IF(AND(AZ16<>"",COUNTIF($AZ$6:$AZ$1005,AZ16)>1),"GSTIN repeated in this sheet; ","")&IF(AND(AS16<>"",COUNTIF($AS$6:$AS$1005,AS16)>1),"PAN repeated in this sheet (same client? put extra GSTINs in Other GSTINs); ","")&IF(AND(BD16>0,V16=""),"Financial year missing; ","")&IF(AND(BD16=0,V16<>""),"Financial year given but no service is Yes; ","")&IF(AND(W16="Yes",AZ16=""),"GST needs a GSTIN; ","")&IF(AND(W16="Yes",X16=""),"GST return frequency missing; ","")&IF(AND(Y16="Yes",TRIM(H16)=""),"TDS needs a TAN; ","")&IF(AND(AA16="Yes",BC16<>"",BC16<>"company",BC16<>"llp"),"ROC is only for a company / LLP; ","")&IF(AND(AA16="Yes",OR(BC16="company",BC16="llp"),TRIM(I16)=""),"ROC needs the CIN / LLPIN; ","")&IF((TRIM(AF16)="")<>(TRIM(AG16)=""),"GST login needs both user ID and password; ","")&IF((TRIM(AH16)="")<>(TRIM(AI16)=""),"Income-tax login needs both user ID and password; ","")&IF((TRIM(AJ16)="")<>(TRIM(AK16)=""),"Income-tax login needs both user ID and password; ","")&IF((TRIM(AL16)="")<>(TRIM(AM16)=""),"TRACES login needs both user ID and password; ","")&IF((TRIM(AN16)="")<>(TRIM(AO16)=""),"MCA login needs both user ID and password; ","")&IF((TRIM(AP16)="")<>(TRIM(AQ16)=""),"E-way bill login needs both user ID and password; ","")
AR17: =IF(NOT(COUNTA(A17:AE17)>0),"",IF(A17="","New client","Update")) | AS17: =IF(BA17<>"",BA17,IF(LEN(AZ17)=15,MID(AZ17,3,10),"")) | AT17: =IF(BB17="","",BB17&IF(D17=""," (guessed from PAN)","")) | AU17: =IF(AZ17="","",IFERROR(INDEX(Lists!$L$2:$L$38,MATCH(LEFT(AZ17,2),Lists!$K$2:$K$38,0)),"Unknown code")) | AV17: =IF(AZ17="","",IFERROR(IF(NOT(AND(LEN(AZ17)=15,ISNUMBER(MATCH(LEFT(AZ17,2),Lists!$K$2:$K$38,0)),SUMPRODUCT(--ISERROR(FIND(MID(MID(AZ17,3,10),{1,2,3,4,5,10},1),"ABCDEFGHIJKLMNOPQRSTUVWXYZ")))=0,SUMPRODUCT(--ISERROR(FIND(MID(MID(AZ17,3,10),{6,7,8,9},1),"0123456789")))=0,ISNUMBER(FIND(MID(AZ17,13,1),"123456789ABCDEFGHIJKLMNOPQRSTUVWXYZ")),MID(AZ17,14,1)="Z")),"Wrong format",IF(MID("0123456789ABCDEFGHIJKLMNOPQRSTUVWXYZ",MOD(36-MOD(SUMPRODUCT(INT((FIND(MID(AZ17,{1,2,3,4,5,6,7,8,9,10,11,12,13,14},1),"0123456789ABCDEFGHIJKLMNOPQRSTUVWXYZ")-1)*{1,2,1,2,1,2,1,2,1,2,1,2,1,2}/36)+MOD((FIND(MID(AZ17,{1,2,3,4,5,6,7,8,9,10,11,12,13,14},1),"0123456789ABCDEFGHIJKLMNOPQRSTUVWXYZ")-1)*{1,2,1,2,1,2,1,2,1,2,1,2,1,2},36)),36),36)+1,1)=MID(AZ17,15,1),"OK","Typo? check digit wrong")),"Wrong format")) | AW17: =IF(BA17="","",IF(AND(LEN(BA17)=10,SUMPRODUCT(--ISERROR(FIND(MID(BA17,{1,2,3,4,5,10},1),"ABCDEFGHIJKLMNOPQRSTUVWXYZ")))=0,SUMPRODUCT(--ISERROR(FIND(MID(BA17,{6,7,8,9},1),"0123456789")))=0),"OK","Wrong format")) | AX17: =IF(TRIM(H17)="","",IF(AND(LEN(UPPER(TRIM(H17)))=10,SUMPRODUCT(--ISERROR(FIND(MID(UPPER(TRIM(H17)),{1,2,3,4,10},1),"ABCDEFGHIJKLMNOPQRSTUVWXYZ")))=0,SUMPRODUCT(--ISERROR(FIND(MID(UPPER(TRIM(H17)),{5,6,7,8,9},1),"0123456789")))=0),"OK","Wrong format")) | AY17: =IF(NOT(COUNTA(A17:AE17)>0),"",IF(BE17<>"","✖ "&LEFT(BE17,LEN(BE17)-2),IF(BD17>0,"✔ Ready — client + "&BD17&" service(s)","✔ Ready — client only"))) | AZ17: =UPPER(SUBSTITUTE(TRIM(F17)," ","")) | BA17: =UPPER(SUBSTITUTE(TRIM(E17)," ","")) | BB17: =IF(D17<>"",D17,IFERROR(VLOOKUP(MID(AS17,4,1),Lists!$E$2:$F$8,2,FALSE),"")) | BC17: =IFERROR(VLOOKUP(BB17,Lists!$A$2:$C$12,3,FALSE),"") | BD17: =COUNTIF(W17:AC17,"Yes") | BE17: =IF(TRIM(B17)="","Legal name missing; ","")&IF(AND(AV17<>"",AV17<>"OK"),"GSTIN: "&AV17&"; ","")&IF(AND(AW17<>"",AW17<>"OK"),"PAN wrong format; ","")&IF(AND(BA17<>"",LEN(AZ17)=15,MID(AZ17,3,10)<>BA17),"PAN does not match GSTIN; ","")&IF(AND(AX17<>"",AX17<>"OK"),"TAN wrong format; ","")&IF(AS17="","PAN missing; ","")&IF(BB17="","Entity type missing; ","")&IF(AND(AZ17<>"",COUNTIF($AZ$6:$AZ$1005,AZ17)>1),"GSTIN repeated in this sheet; ","")&IF(AND(AS17<>"",COUNTIF($AS$6:$AS$1005,AS17)>1),"PAN repeated in this sheet (same client? put extra GSTINs in Other GSTINs); ","")&IF(AND(BD17>0,V17=""),"Financial year missing; ","")&IF(AND(BD17=0,V17<>""),"Financial year given but no service is Yes; ","")&IF(AND(W17="Yes",AZ17=""),"GST needs a GSTIN; ","")&IF(AND(W17="Yes",X17=""),"GST return frequency missing; ","")&IF(AND(Y17="Yes",TRIM(H17)=""),"TDS needs a TAN; ","")&IF(AND(AA17="Yes",BC17<>"",BC17<>"company",BC17<>"llp"),"ROC is only for a company / LLP; ","")&IF(AND(AA17="Yes",OR(BC17="company",BC17="llp"),TRIM(I17)=""),"ROC needs the CIN / LLPIN; ","")&IF((TRIM(AF17)="")<>(TRIM(AG17)=""),"GST login needs both user ID and password; ","")&IF((TRIM(AH17)="")<>(TRIM(AI17)=""),"Income-tax login needs both user ID and password; ","")&IF((TRIM(AJ17)="")<>(TRIM(AK17)=""),"Income-tax login needs both user ID and password; ","")&IF((TRIM(AL17)="")<>(TRIM(AM17)=""),"TRACES login needs both user ID and password; ","")&IF((TRIM(AN17)="")<>(TRIM(AO17)=""),"MCA login needs both user ID and password; ","")&IF((TRIM(AP17)="")<>(TRIM(AQ17)=""),"E-way bill login needs both user ID and password; ","")
... AR1005: =IF(NOT(COUNTA(A1005:AE1005)>0),"",IF(A1005="","New client","Update")) | AS1005: =IF(BA1005<>"",BA1005,IF(LEN(AZ1005)=15,MID(AZ1005,3,10),"")) | AT1005: =IF(BB1005="","",BB1005&IF(D1005=""," (guessed from PAN)","")) | AU1005: =IF(AZ1005="","",IFERROR(INDEX(Lists!$L$2:$L$38,MATCH(LEFT(AZ1005,2),Lists!$K$2:$K$38,0)),"Unknown code")) | AV1005: =IF(AZ1005="","",IFERROR(IF(NOT(AND(LEN(AZ1005)=15,ISNUMBER(MATCH(LEFT(AZ1005,2),Lists!$K$2:$K$38,0)),SUMPRODUCT(--ISERROR(FIND(MID(MID(AZ1005,3,10),{1,2,3,4,5,10},1),"ABCDEFGHIJKLMNOPQRSTUVWXYZ")))=0,SUMPRODUCT(--ISERROR(FIND(MID(MID(AZ1005,3,10),{6,7,8,9},1),"0123456789")))=0,ISNUMBER(FIND(MID(AZ1005,13,1),"123456789ABCDEFGHIJKLMNOPQRSTUVWXYZ")),MID(AZ1005,14,1)="Z")),"Wrong format",IF(MID("0123456789ABCDEFGHIJKLMNOPQRSTUVWXYZ",MOD(36-MOD(SUMPRODUCT(INT((FIND(MID(AZ1005,{1,2,3,4,5,6,7,8,9,10,11,12,13,14},1),"0123456789ABCDEFGHIJKLMNOPQRSTUVWXYZ")-1)*{1,2,1,2,1,2,1,2,1,2,1,2,1,2}/36)+MOD((FIND(MID(AZ1005,{1,2,3,4,5,6,7,8,9,10,11,12,13,14},1),"0123456789ABCDEFGHIJKLMNOPQRSTUVWXYZ")-1)*{1,2,1,2,1,2,1,2,1,2,1,2,1,2},36)),36),36)+1,1)=MID(AZ1005,15,1),"OK","Typo? check digit wrong")),"Wrong format")) | AW1005: =IF(BA1005="","",IF(AND(LEN(BA1005)=10,SUMPRODUCT(--ISERROR(FIND(MID(BA1005,{1,2,3,4,5,10},1),"ABCDEFGHIJKLMNOPQRSTUVWXYZ")))=0,SUMPRODUCT(--ISERROR(FIND(MID(BA1005,{6,7,8,9},1),"0123456789")))=0),"OK","Wrong format")) | AX1005: =IF(TRIM(H1005)="","",IF(AND(LEN(UPPER(TRIM(H1005)))=10,SUMPRODUCT(--ISERROR(FIND(MID(UPPER(TRIM(H1005)),{1,2,3,4,10},1),"ABCDEFGHIJKLMNOPQRSTUVWXYZ")))=0,SUMPRODUCT(--ISERROR(FIND(MID(UPPER(TRIM(H1005)),{5,6,7,8,9},1),"0123456789")))=0),"OK","Wrong format")) | AY1005: =IF(NOT(COUNTA(A1005:AE1005)>0),"",IF(BE1005<>"","✖ "&LEFT(BE1005,LEN(BE1005)-2),IF(BD1005>0,"✔ Ready — client + "&BD1005&" service(s)","✔ Ready — client only"))) | AZ1005: =UPPER(SUBSTITUTE(TRIM(F1005)," ","")) | BA1005: =UPPER(SUBSTITUTE(TRIM(E1005)," ","")) | BB1005: =IF(D1005<>"",D1005,IFERROR(VLOOKUP(MID(AS1005,4,1),Lists!$E$2:$F$8,2,FALSE),"")) | BC1005: =IFERROR(VLOOKUP(BB1005,Lists!$A$2:$C$12,3,FALSE),"") | BD1005: =COUNTIF(W1005:AC1005,"Yes") | BE1005: =IF(TRIM(B1005)="","Legal name missing; ","")&IF(AND(AV1005<>"",AV1005<>"OK"),"GSTIN: "&AV1005&"; ","")&IF(AND(AW1005<>"",AW1005<>"OK"),"PAN wrong format; ","")&IF(AND(BA1005<>"",LEN(AZ1005)=15,MID(AZ1005,3,10)<>BA1005),"PAN does not match GSTIN; ","")&IF(AND(AX1005<>"",AX1005<>"OK"),"TAN wrong format; ","")&IF(AS1005="","PAN missing; ","")&IF(BB1005="","Entity type missing; ","")&IF(AND(AZ1005<>"",COUNTIF($AZ$6:$AZ$1005,AZ1005)>1),"GSTIN repeated in this sheet; ","")&IF(AND(AS1005<>"",COUNTIF($AS$6:$AS$1005,AS1005)>1),"PAN repeated in this sheet (same client? put extra GSTINs in Other GSTINs); ","")&IF(AND(BD1005>0,V1005=""),"Financial year missing; ","")&IF(AND(BD1005=0,V1005<>""),"Financial year given but no service is Yes; ","")&IF(AND(W1005="Yes",AZ1005=""),"GST needs a GSTIN; ","")&IF(AND(W1005="Yes",X1005=""),"GST return frequency missing; ","")&IF(AND(Y1005="Yes",TRIM(H1005)=""),"TDS needs a TAN; ","")&IF(AND(AA1005="Yes",BC1005<>"",BC1005<>"company",BC1005<>"llp"),"ROC is only for a company / LLP; ","")&IF(AND(AA1005="Yes",OR(BC1005="company",BC1005="llp"),TRIM(I1005)=""),"ROC needs the CIN / LLPIN; ","")&IF((TRIM(AF1005)="")<>(TRIM(AG1005)=""),"GST login needs both user ID and password; ","")&IF((TRIM(AH1005)="")<>(TRIM(AI1005)=""),"Income-tax login needs both user ID and password; ","")&IF((TRIM(AJ1005)="")<>(TRIM(AK1005)=""),"Income-tax login needs both user ID and password; ","")&IF((TRIM(AL1005)="")<>(TRIM(AM1005)=""),"TRACES login needs both user ID and password; ","")&IF((TRIM(AN1005)="")<>(TRIM(AO1005)=""),"MCA login needs both user ID and password; ","")&IF((TRIM(AP1005)="")<>(TRIM(AQ1005)=""),"E-way bill login needs both user ID and password; ","")

Sheet Logins
A1: More portal logins (optional) — other GSTINs, TRACES taxpayer, E-invoice; one row per login
A2: A client's main logins go on its own row on 'Clients' (Logins columns). Passwords are sealed (encrypted) when imported. Export masks them unless you choose Export with passwords — such a file holds real passwords: share it only with people who may see them, and delete it after use.
A3: Client code | B3: Legal name (as on Clients) | C3: Portal | D3: For GSTIN / TAN | E3: User ID | F3: Password | G3: Check
A4: EXAMPLE | B4: Sharma Traders | C4: GST | D4: 07ABCPS1234K1ZO | E4: sharma_gst | F4: •••••••• | G4: =IF(COUNTA(A4:F4)=0,"",IF(A4="EXAMPLE","Example (skipped)",IF(OR(C4="",E4="",F4=""),"✖ Portal, User ID and Password are all needed",IF(AND(A4="",COUNTIF(Clients!$B$5:$B$1005,B4)=0),"Not on Clients — will match a portal client by name",IF(AND(C4="GST",D4<>"",COUNTIF(Clients!$AZ$5:$AZ$1005,UPPER(D4))=0,COUNTIF(Clients!$G$5:$G$1005,"*"&UPPER(D4)&"*")=0),"GSTIN not on Clients — will be checked in the portal","✔ OK")))))
G5: =IF(COUNTA(A5:F5)=0,"",IF(A5="EXAMPLE","Example (skipped)",IF(OR(C5="",E5="",F5=""),"✖ Portal, User ID and Password are all needed",IF(AND(A5="",COUNTIF(Clients!$B$5:$B$1005,B5)=0),"Not on Clients — will match a portal client by name",IF(AND(C5="GST",D5<>"",COUNTIF(Clients!$AZ$5:$AZ$1005,UPPER(D5))=0,COUNTIF(Clients!$G$5:$G$1005,"*"&UPPER(D5)&"*")=0),"GSTIN not on Clients — will be checked in the portal","✔ OK")))))
G6: =IF(COUNTA(A6:F6)=0,"",IF(A6="EXAMPLE","Example (skipped)",IF(OR(C6="",E6="",F6=""),"✖ Portal, User ID and Password are all needed",IF(AND(A6="",COUNTIF(Clients!$B$5:$B$1005,B6)=0),"Not on Clients — will match a portal client by name",IF(AND(C6="GST",D6<>"",COUNTIF(Clients!$AZ$5:$AZ$1005,UPPER(D6))=0,COUNTIF(Clients!$G$5:$G$1005,"*"&UPPER(D6)&"*")=0),"GSTIN not on Clients — will be checked in the portal","✔ OK")))))
G7: =IF(COUNTA(A7:F7)=0,"",IF(A7="EXAMPLE","Example (skipped)",IF(OR(C7="",E7="",F7=""),"✖ Portal, User ID and Password are all needed",IF(AND(A7="",COUNTIF(Clients!$B$5:$B$1005,B7)=0),"Not on Clients — will match a portal client by name",IF(AND(C7="GST",D7<>"",COUNTIF(Clients!$AZ$5:$AZ$1005,UPPER(D7))=0,COUNTIF(Clients!$G$5:$G$1005,"*"&UPPER(D7)&"*")=0),"GSTIN not on Clients — will be checked in the portal","✔ OK")))))
G8: =IF(COUNTA(A8:F8)=0,"",IF(A8="EXAMPLE","Example (skipped)",IF(OR(C8="",E8="",F8=""),"✖ Portal, User ID and Password are all needed",IF(AND(A8="",COUNTIF(Clients!$B$5:$B$1005,B8)=0),"Not on Clients — will match a portal client by name",IF(AND(C8="GST",D8<>"",COUNTIF(Clients!$AZ$5:$AZ$1005,UPPER(D8))=0,COUNTIF(Clients!$G$5:$G$1005,"*"&UPPER(D8)&"*")=0),"GSTIN not on Clients — will be checked in the portal","✔ OK")))))
G9: =IF(COUNTA(A9:F9)=0,"",IF(A9="EXAMPLE","Example (skipped)",IF(OR(C9="",E9="",F9=""),"✖ Portal, User ID and Password are all needed",IF(AND(A9="",COUNTIF(Clients!$B$5:$B$1005,B9)=0),"Not on Clients — will match a portal client by name",IF(AND(C9="GST",D9<>"",COUNTIF(Clients!$AZ$5:$AZ$1005,UPPER(D9))=0,COUNTIF(Clients!$G$5:$G$1005,"*"&UPPER(D9)&"*")=0),"GSTIN not on Clients — will be checked in the portal","✔ OK")))))
G10: =IF(COUNTA(A10:F10)=0,"",IF(A10="EXAMPLE","Example (skipped)",IF(OR(C10="",E10="",F10=""),"✖ Portal, User ID and Password are all needed",IF(AND(A10="",COUNTIF(Clients!$B$5:$B$1005,B10)=0),"Not on Clients — will match a portal client by name",IF(AND(C10="GST",D10<>"",COUNTIF(Clients!$AZ$5:$AZ$1005,UPPER(D10))=0,COUNTIF(Clients!$G$5:$G$1005,"*"&UPPER(D10)&"*")=0),"GSTIN not on Clients — will be checked in the portal","✔ OK")))))
G11: =IF(COUNTA(A11:F11)=0,"",IF(A11="EXAMPLE","Example (skipped)",IF(OR(C11="",E11="",F11=""),"✖ Portal, User ID and Password are all needed",IF(AND(A11="",COUNTIF(Clients!$B$5:$B$1005,B11)=0),"Not on Clients — will match a portal client by name",IF(AND(C11="GST",D11<>"",COUNTIF(Clients!$AZ$5:$AZ$1005,UPPER(D11))=0,COUNTIF(Clients!$G$5:$G$1005,"*"&UPPER(D11)&"*")=0),"GSTIN not on Clients — will be checked in the portal","✔ OK")))))
G12: =IF(COUNTA(A12:F12)=0,"",IF(A12="EXAMPLE","Example (skipped)",IF(OR(C12="",E12="",F12=""),"✖ Portal, User ID and Password are all needed",IF(AND(A12="",COUNTIF(Clients!$B$5:$B$1005,B12)=0),"Not on Clients — will match a portal client by name",IF(AND(C12="GST",D12<>"",COUNTIF(Clients!$AZ$5:$AZ$1005,UPPER(D12))=0,COUNTIF(Clients!$G$5:$G$1005,"*"&UPPER(D12)&"*")=0),"GSTIN not on Clients — will be checked in the portal","✔ OK")))))
